Workbook

Sheet Students Data
A1: Student ID | B1: Full Name | C1: First Name | D1: Gender | E1: Course | F1: Math | G1: Science | H1: English | I1: Total Marks | J1: Percentage | K1: Grade | L1: Rank | M1: 80 up math&sci | N1: Top Performace | O1: Fees | P1: Disscount % | Q1: Disscount Amount | R1: Final Fess | S1: DOB | T1: Age | U1: Join Date | V1: Since Join
A3: ST001 | B3: Tej Patel | C3: =LEFT(B3,FIND(" ",B3)-1) -> Tej | D3: M | E3: AI | F3: 98 | G3: 96 | H3: 97 | I3: =SUM(F3:H3) -> 291 | J3: =(I3/300)*100 -> 97 | K3: =IF(J3>=90,"A+",IF(J3>=80,"A",IF(J3>=70,"B",IF(J3>=60,"C","Fail")))) -> A+ | L3: =IF(J3>=97,"First", IF(J3>=96,"Second", IF(J3>=95,"Third", IF(J3>=94,"Fourth", IF(J3>=93.66666666,"Fifth","Normal"))))) -> First | M3: =IF(AND(F3>=80,G3>=80),"Eligible","Not Eligible") -> Eligible | N3: =IF(OR(F3>=90,G3>=90),"Top Performer","Normal") -> Top Performer | O3: 50000 | P3: =IF(J3>=90,25%,IF(J3>=80,20%,IF(J3>=70,10%,0))) -> 0.25 | Q3: =O3*P3 -> 12500 | R3: =O3-Q3 -> 37500 | S3: 38056 | T3: =DATEDIF(S3,TODAY(),"Y") -> 22 | U3: 45458 | V3: =DATEDIF(U3,TODAY(),"D") & " Days" -> 743 Days
A4: ST002 | B4: Diya Patel | C4: =LEFT(B4,FIND(" ",B4)-1) -> Diya | D4: F | E4: AI | F4: 95 | G4: 97 | H4: 96 | I4: =SUM(F4:H4) -> 288 | J4: =(I4/300)*100 -> 96 | K4: =IF(J4>=90,"A+",IF(J4>=80,"A",IF(J4>=70,"B",IF(J4>=60,"C","Fail")))) -> A+ | L4: =IF(J4>=97,"First", IF(J4>=96,"Second", IF(J4>=95,"Third", IF(J4>=94,"Fourth", IF(J4>=93.66666666,"Fifth","Normal"))))) -> Second | M4: =IF(AND(F4>=80,G4>=80),"Eligible","Not Eligible") -> Eligible | N4: =IF(OR(F4>=90,G4>=90),"Top Performer","Normal") -> Top Performer | O4: 50000 | P4: =IF(J4>=90,25%,IF(J4>=80,20%,IF(J4>=70,10%,0))) -> 0.25 | Q4: =O4*P4 -> 12500 | R4: =O4-Q4 -> 37500 | S4: 38213 | T4: =DATEDIF(S4,TODAY(),"Y") -> 21 | U4: 45459 | V4: =DATEDIF(U4,TODAY(),"D") & " Days" -> 742 Days
A5: ST003 | B5: Vandita Patel | C5: =LEFT(B5,FIND(" ",B5)-1) -> Vandita | D5: F | E5: AI | F5: 96 | G5: 95 | H5: 94 | I5: =SUM(F5:H5) -> 285 | J5: =(I5/300)*100 -> 95 | K5: =IF(J5>=90,"A+",IF(J5>=80,"A",IF(J5>=70,"B",IF(J5>=60,"C","Fail")))) -> A+ | L5: =IF(J5>=97,"First", IF(J5>=96,"Second", IF(J5>=95,"Third", IF(J5>=94,"Fourth", IF(J5>=93.66666666,"Fifth","Normal"))))) -> Third | M5: =IF(AND(F5>=80,G5>=80),"Eligible","Not Eligible") -> Eligible | N5: =IF(OR(F5>=90,G5>=90),"Top Performer","Normal") -> Top Performer | O5: 50000 | P5: =IF(J5>=90,25%,IF(J5>=80,20%,IF(J5>=70,10%,0))) -> 0.25 | Q5: =O5*P5 -> 12500 | R5: =O5-Q5 -> 37500 | S5: 36899 | T5: =DATEDIF(S5,TODAY(),"Y") -> 25 | U5: 45462 | V5: =DATEDIF(U5,TODAY(),"D") & " Days" -> 739 Days
A6: ST004 | B6: Krish Patel | C6: =LEFT(B6,FIND(" ",B6)-1) -> Krish | D6: M | E6: DS | F6: 88 | G6: 86 | H6: 90 | I6: =SUM(F6:H6) -> 264 | J6: =(I6/300)*100 -> 88 | K6: =IF(J6>=90,"A+",IF(J6>=80,"A",IF(J6>=70,"B",IF(J6>=60,"C","Fail")))) -> A | L6: =IF(J6>=97,"First", IF(J6>=96,"Second", IF(J6>=95,"Third", IF(J6>=94,"Fourth", IF(J6>=93.66666666,"Fifth","Normal"))))) -> Normal | M6: =IF(AND(F6>=80,G6>=80),"Eligible","Not Eligible") -> Eligible | N6: =IF(OR(F6>=90,G6>=90),"Top Performer","Normal") -> Normal | O6: 45000 | P6: =IF(J6>=90,25%,IF(J6>=80,20%,IF(J6>=70,10%,0))) -> 0.2 | Q6: =O6*P6 -> 9000 | R6: =O6-Q6 -> 36000 | S6: 38447 | T6: =DATEDIF(S6,TODAY(),"Y") -> 21 | U6: 45453 | V6: =DATEDIF(U6,TODAY(),"D") & " Days" -> 748 Days
A7: ST005 | B7: Meet Shah | C7: =LEFT(B7,FIND(" ",B7)-1) -> Meet | D7: M | E7: ML | F7: 85 | G7: 82 | H7: 80 | I7: =SUM(F7:H7) -> 247 | J7: =(I7/300)*100 -> 82.333333 | K7: =IF(J7>=90,"A+",IF(J7>=80,"A",IF(J7>=70,"B",IF(J7>=60,"C","Fail")))) -> A | L7: =IF(J7>=97,"First", IF(J7>=96,"Second", IF(J7>=95,"Third", IF(J7>=94,"Fourth", IF(J7>=93.66666666,"Fifth","Normal"))))) -> Normal | M7: =IF(AND(F7>=80,G7>=80),"Eligible","Not Eligible") -> Eligible | N7: =IF(OR(F7>=90,G7>=90),"Top Performer","Normal") -> Normal | O7: 45000 | P7: =IF(J7>=90,25%,IF(J7>=80,20%,IF(J7>=70,10%,0))) -> 0.2 | Q7: =O7*P7 -> 9000 | R7: =O7-Q7 -> 36000 | S7: 38548 | T7: =DATEDIF(S7,TODAY(),"Y") -> 20 | U7: 45463 | V7: =DATEDIF(U7,TODAY(),"D") & " Days" -> 738 Days
A8: ST006 | B8: Priya Patel | C8: =LEFT(B8,FIND(" ",B8)-1) -> Priya | D8: F | E8: AI | F8: 78 | G8: 80 | H8: 82 | I8: =SUM(F8:H8) -> 240 | J8: =(I8/300)*100 -> 80 | K8: =IF(J8>=90,"A+",IF(J8>=80,"A",IF(J8>=70,"B",IF(J8>=60,"C","Fail")))) -> A | L8: =IF(J8>=97,"First", IF(J8>=96,"Second", IF(J8>=95,"Third", IF(J8>=94,"Fourth", IF(J8>=93.66666666,"Fifth","Normal"))))) -> Normal | M8: =IF(AND(F8>=80,G8>=80),"Eligible","Not Eligible") -> Not Eligible | N8: =IF(OR(F8>=90,G8>=90),"Top Performer","Normal") -> Normal | O8: 50000 | P8: =IF(J8>=90,25%,IF(J8>=80,20%,IF(J8>=70,10%,0))) -> 0.2 | Q8: =O8*P8 -> 10000 | R8: =O8-Q8 -> 40000 | S8: 38677 | T8: =DATEDIF(S8,TODAY(),"Y") -> 20 | U8: 45458 | V8: =DATEDIF(U8,TODAY(),"D") & " Days" -> 743 Days
A9: ST007 | B9: Yash Patel | C9: =LEFT(B9,FIND(" ",B9)-1) -> Yash | D9: M | E9: DS | F9: 70 | G9: 75 | H9: 72 | I9: =SUM(F9:H9) -> 217 | J9: =(I9/300)*100 -> 72.333333 | K9: =IF(J9>=90,"A+",IF(J9>=80,"A",IF(J9>=70,"B",IF(J9>=60,"C","Fail")))) -> B | L9: =IF(J9>=97,"First", IF(J9>=96,"Second", IF(J9>=95,"Third", IF(J9>=94,"Fourth", IF(J9>=93.66666666,"Fifth","Normal"))))) -> Normal | M9: =IF(AND(F9>=80,G9>=80),"Eligible","Not Eligible") -> Not Eligible | N9: =IF(OR(F9>=90,G9>=90),"Top Performer","Normal") -> Normal | O9: 45000 | P9: =IF(J9>=90,25%,IF(J9>=80,20%,IF(J9>=70,10%,0))) -> 0.1 | Q9: =O9*P9 -> 4500 | R9: =O9-Q9 -> 40500 | S9: 38414 | T9: =DATEDIF(S9,TODAY(),"Y") -> 21 | U9: 45455 | V9: =DATEDIF(U9,TODAY(),"D") & " Days" -> 746 Days
A10: ST008 | B10: Riya Shah | C10: =LEFT(B10,FIND(" ",B10)-1) -> Riya | D10: F | E10: ML | F10: 68 | G10: 70 | H10: 65 | I10: =SUM(F10:H10) -> 203 | J10: =(I10/300)*100 -> 67.666667 | K10: =IF(J10>=90,"A+",IF(J10>=80,"A",IF(J10>=70,"B",IF(J10>=60,"C","Fail")))) -> C | L10: =IF(J10>=97,"First", IF(J10>=96,"Second", IF(J10>=95,"Third", IF(J10>=94,"Fourth", IF(J10>=93.66666666,"Fifth","Normal"))))) -> Normal | M10: =IF(AND(F10>=80,G10>=80),"Eligible","Not Eligible") -> Not Eligible | N10: =IF(OR(F10>=90,G10>=90),"Top Performer","Normal") -> Normal | O10: 45000 | P10: =IF(J10>=90,25%,IF(J10>=80,20%,IF(J10>=70,10%,0))) -> 0 | Q10: =O10*P10 -> 0 | R10: =O10-Q10 -> 45000 | S10: 38614 | T10: =DATEDIF(S10,TODAY(),"Y") -> 20 | U10: 45461 | V10: =DATEDIF(U10,TODAY(),"D") & " Days" -> 740 Days
A11: ST009 | B11: Aarav Patel | C11: =LEFT(B11,FIND(" ",B11)-1) -> Aarav | D11: M | E11: AI | F11: 60 | G11: 62 | H11: 64 | I11: =SUM(F11:H11) -> 186 | J11: =(I11/300)*100 -> 62 | K11: =IF(J11>=90,"A+",IF(J11>=80,"A",IF(J11>=70,"B",IF(J11>=60,"C","Fail")))) -> C | L11: =IF(J11>=97,"First", IF(J11>=96,"Second", IF(J11>=95,"Third", IF(J11>=94,"Fourth", IF(J11>=93.66666666,"Fifth","Normal"))))) -> Normal | M11: =IF(AND(F11>=80,G11>=80),"Eligible","Not Eligible") -> Not Eligible | N11: =IF(OR(F11>=90,G11>=90),"Top Performer","Normal") -> Normal | O11: 50000 | P11: =IF(J11>=90,25%,IF(J11>=80,20%,IF(J11>=70,10%,0))) -> 0 | Q11: =O11*P11 -> 0 | R11: =O11-Q11 -> 50000 | S11: 38360 | T11: =DATEDIF(S11,TODAY(),"Y") -> 21 | U11: 45465 | V11: =DATEDIF(U11,TODAY(),"D") & " Days" -> 736 Days
A12: ST010 | B12: Kavya Patel | C12: =LEFT(B12,FIND(" ",B12)-1) -> Kavya | D12: F | E12: DS | F12: 58 | G12: 55 | H12: 60 | I12: =SUM(F12:H12) -> 173 | J12: =(I12/300)*100 -> 57.666667 | K12: =IF(J12>=90,"A+",IF(J12>=80,"A",IF(J12>=70,"B",IF(J12>=60,"C","Fail")))) -> Fail | L12: =IF(J12>=97,"First", IF(J12>=96,"Second", IF(J12>=95,"Third", IF(J12>=94,"Fourth", IF(J12>=93.66666666,"Fifth","Normal"))))) -> Normal | M12: =IF(AND(F12>=80,G12>=80),"Eligible","Not Eligible") -> Not Eligible | N12: =IF(OR(F12>=90,G12>=90),"Top Performer","Normal") -> Normal | O12: 45000 | P12: =IF(J12>=90,25%,IF(J12>=80,20%,IF(J12>=70,10%,0))) -> 0 | Q12: =O12*P12 -> 0 | R12: =O12-Q12 -> 45000 | S12: 38394 | T12: =DATEDIF(S12,TODAY(),"Y") -> 21 | U12: 45451 | V12: =DATEDIF(U12,TODAY(),"D") & " Days" -> 750 Days
A13: ST011 | B13: Jay Patel | C13: =LEFT(B13,FIND(" ",B13)-1) -> Jay | D13: M | E13: ML | F13: 52 | G13: 50 | H13: 55 | I13: =SUM(F13:H13) -> 157 | J13: =(I13/300)*100 -> 52.333333 | K13: =IF(J13>=90,"A+",IF(J13>=80,"A",IF(J13>=70,"B",IF(J13>=60,"C","Fail")))) -> Fail | L13: =IF(J13>=97,"First", IF(J13>=96,"Second", IF(J13>=95,"Third", IF(J13>=94,"Fourth", IF(J13>=93.66666666,"Fifth","Normal"))))) -> Normal | M13: =IF(AND(F13>=80,G13>=80),"Eligible","Not Eligible") -> Not Eligible | N13: =IF(OR(F13>=90,G13>=90),"Top Performer","Normal") -> Normal | O13: 45000 | P13: =IF(J13>=90,25%,IF(J13>=80,20%,IF(J13>=70,10%,0))) -> 0 | Q13: =O13*P13 -> 0 | R13: =O13-Q13 -> 45000 | S13: 38711 | T13: =DATEDIF(S13,TODAY(),"Y") -> 20 | U13: 45468 | V13: =DATEDIF(U13,TODAY(),"D") & " Days" -> 733 Days
A14: ST012 | B14: Neha Shah | C14: =LEFT(B14,FIND(" ",B14)-1) -> Neha | D14: F | E14: AI | F14: 45 | G14: 48 | H14: 50 | I14: =SUM(F14:H14) -> 143 | J14: =(I14/300)*100 -> 47.666667 | K14: =IF(J14>=90,"A+",IF(J14>=80,"A",IF(J14>=70,"B",IF(J14>=60,"C","Fail")))) -> Fail | L14: =IF(J14>=97,"First", IF(J14>=96,"Second", IF(J14>=95,"Third", IF(J14>=94,"Fourth", IF(J14>=93.66666666,"Fifth","Normal"))))) -> Normal | M14: =IF(AND(F14>=80,G14>=80),"Eligible","Not Eligible") -> Not Eligible | N14: =IF(OR(F14>=90,G14>=90),"Top Performer","Normal") -> Normal | O14: 50000 | P14: =IF(J14>=90,25%,IF(J14>=80,20%,IF(J14>=70,10%,0))) -> 0 | Q14: =O14*P14 -> 0 | R14: =O14-Q14 -> 50000 | S14: 38626 | T14: =DATEDIF(S14,TODAY(),"Y") -> 20 | U14: 45471 | V14: =DATEDIF(U14,TODAY(),"D") & " Days" -> 730 Days
... A22: ST020 | B22: Ronak Patel | C22: =LEFT(B22,FIND(" ",B22)-1) -> Ronak | D22: M | E22: AI | F22: 72 | G22: 75 | H22: 78 | I22: =SUM(F22:H22) -> 225 | J22: =(I22/300)*100 -> 75 | K22: =IF(J22>=90,"A+",IF(J22>=80,"A",IF(J22>=70,"B",IF(J22>=60,"C","Fail")))) -> B | L22: =IF(J22>=97,"First", IF(J22>=96,"Second", IF(J22>=95,"Third", IF(J22>=94,"Fourth", IF(J22>=93.66666666,"Fifth","Normal"))))) -> Normal | M22: =IF(AND(F22>=80,G22>=80),"Eligible","Not Eligible") -> Not Eligible | N22: =IF(OR(F22>=90,G22>=90),"Top Performer","Normal") -> Normal | O22: 50000 | P22: =IF(J22>=90,25%,IF(J22>=80,20%,IF(J22>=70,10%,0))) -> 0.1 | Q22: =O22*P22 -> 5000 | R22: =O22-Q22 -> 45000 | S22: 38441 | T22: =DATEDIF(S22,TODAY(),"Y") -> 21 | U22: 45465 | V22: =DATEDIF(U22,TODAY(),"D") & " Days" -> 736 Days
B24: Dashboard
B27: Rank | C27: Student name
B28: First | C28: =INDEX(B3:B22,MATCH(LARGE(J3:J22,1),J3:J22,0)) -> Tej Patel | E28: Total Students | H28: Highest | K28: Student above 60 marks in maths | N28: Total Fees Collected
B29: Second | C29: =INDEX(B3:B22,MATCH(LARGE(J3:J22,2),J3:J22,0)) -> Diya Patel | E29: =COUNTA('Students Data'!A3:A21) -> 19 | H29: =MAX('Students Data'!J3:J22) -> 97 | J29: =COUNTIFS(F3:F22,">60") -> 16 | N29: =SUM('Students Data'!R3:R22) -> 812500
B30: Third | C30: =INDEX(B3:B22,MATCH(LARGE(J3:J22,3),J3:J22,0)) -> Vandita Patel
B31: fourth | C31: =INDEX(B3:B22,MATCH(LARGE(J3:J22,4),J3:J22,0)) -> Dev Patel | E31: Avg Percentage | H31: Lowest | J31: Top Students above 80% | N31: AI Student | P31: DS Student
B32: Fifth | C32: =INDEX(B3:B22,MATCH(LARGE(J3:J22,5),J3:J22,0)) -> Mansi Patel | E32: =AVERAGE('Students Data'!J3:J22) -> 78.383333 | H32: =MIN('Students Data'!J3:J22) -> 47.666667 | J32: =COUNTIF('Students Data'!J3:J22,">=80") -> 11 | N32: =COUNTIF('Students Data'!E3:E22,"AI") -> 9 | P32: =COUNTIF('Students Data'!E3:E22,"DS") -> 6
O33: ML Student
E34: Pass student | H34: Fail Students | K34: Average Percenatge of AI students | O34: =COUNTIF('Students Data'!E3:E22,"ML") -> 5
E35: {=SUM(COUNTIF(K24:K38,{"A+","A","B+","B","C+","C"}))} -> 0 | H35: =COUNTIF(K3:K22,"Fail") -> 3 | K35: =AVERAGEIFS(J$3:J$22,E$3:E$22,"AI") -> 79.407407
N37: Total Fees Collected from AI student
N38: =SUMIFS('Students Data'!R3:R22,'Students Data'!E3:E22,"AI") -> 385000

Sheet Sales Data
A1: Product code | B1: Product | C1: Region | D1: Salesperson | E1: Month | F1: Unit Price | G1: Qty | H1: Total Sales | I1: Disscount | J1: Round Sales | K1: Celling Sales | L1: Floor Sales | N1: Dashboard
A3: P001 | B3: Laptop | C3: North | D3: Tej Patel | E3: Jan | F3: 55000 | G3: 2 | H3: =F3*G3 -> 110000 | I3: =IF(H3>=50000,"10%","5%") -> 10% | J3: =ROUND(H3,-2) -> 110000 | K3: =CEILING(H3,1000) -> 110000 | L3: =FLOOR(H3,1000) -> 110000
A4: P002 | B4: Mouse | C4: South | D4: Diya Patel | E4: Jan | F4: 800 | G4: 15 | H4: =F4*G4 -> 12000 | I4: =IF(H4>=50000,"10%","5%") -> 5% | J4: =ROUND(H4,-2) -> 12000 | K4: =CEILING(H4,1000) -> 12000 | L4: =FLOOR(H4,1000) -> 12000 | O4: North Region Laptop Sales | T4: Row Labels | U4: Sum of Total Sales | V4: Sum of Unit Price
A5: P003 | B5: Keyboard | C5: East | D5: Vandita Patel | E5: Feb | F5: 1500 | G5: 10 | H5: =F5*G5 -> 15000 | I5: =IF(H5>=50000,"10%","5%") -> 5% | J5: =ROUND(H5,-2) -> 15000 | K5: =CEILING(H5,1000) -> 15000 | L5: =FLOOR(H5,1000) -> 15000 | O5: =SUMIFS(H:H,C:C,"North",B:B,"Laptop") -> 110000 | T5: Keyboard | U5: 233900 | V5: 28800
A6: P004 | B6: Moniter | C6: West | D6: Krish Patel | E6: Feb | F6: 12000 | G6: 3 | H6: =F6*G6 -> 36000 | I6: =IF(H6>=50000,"10%","5%") -> 5% | J6: =ROUND(H6,-2) -> 36000 | K6: =CEILING(H6,1000) -> 36000 | L6: =FLOOR(H6,1000) -> 36000 | T6: Laptop | U6: 172350 | V6: 116600
A7: P005 | B7: Printer | C7: North | D7: Meet Shah | E7: March | F7: 18000 | G7: 2 | H7: =F7*G7 -> 36000 | I7: =IF(H7>=50000,"10%","5%") -> 5% | J7: =ROUND(H7,-2) -> 36000 | K7: =CEILING(H7,1000) -> 36000 | L7: =FLOOR(H7,1000) -> 36000 | O7: Product Code P005 Product price | T7: Moniter | U7: 225500 | V7: 59500
A8: P006 | B8: Laptop | C8: South | D8: Priya Patel | E8: March | F8: 60000 | G8: 1 | H8: =F8*G8 -> 60000 | I8: =IF(H8>=50000,"10%","5%") -> 10% | J8: =ROUND(H8,-2) -> 60000 | K8: =CEILING(H8,1000) -> 60000 | L8: =FLOOR(H8,1000) -> 60000 | O8: =VLOOKUP("P005",A:H,6,FALSE) -> 18000 | T8: Mouse | U8: 78600 | V8: 4950
A9: P007 | B9: Mouse | C9: East | D9: Yash Patel | E9: April | F9: 750 | G9: 20 | H9: =F9*G9 -> 15000 | I9: =IF(H9>=50000,"10%","5%") -> 5% | J9: =ROUND(H9,-2) -> 15000 | K9: =CEILING(H9,1000) -> 15000 | L9: =FLOOR(H9,1000) -> 15000 | T9: Printer | U9: 456000 | V9: 198000
A10: P008 | B10: Keyboard | C10: West | D10: Riya Shah | E10: April | F10: 1800 | G10: 8 | H10: =F10*G10 -> 14400 | I10: =IF(H10>=50000,"10%","5%") -> 5% | J10: =ROUND(H10,-2) -> 14400 | K10: =CEILING(H10,1000) -> 15000 | L10: =FLOOR(H10,1000) -> 14000 | O10: First 5 Total Sales ka sum | T10: Grand Total | U10: 1166350 | V10: 407850
A11: P009 | B11: Moniter | C11: North | D11: Aarav Patel | E11: May | F11: 13000 | G11: 4 | H11: =F11*G11 -> 52000 | I11: =IF(H11>=50000,"10%","5%") -> 10% | J11: =ROUND(H11,-2) -> 52000 | K11: =CEILING(H11,1000) -> 52000 | L11: =FLOOR(H11,1000) -> 52000 | O11: =SUM(OFFSET(L3,0,0,5,1)) -> 209000
A12: P010 | B12: Printer | C12: South | D12: Kavya Patel | E12: May | F12: 60000 | G12: 3 | H12: =F12*G12 -> 180000 | I12: =IF(H12>=50000,"10%","5%") -> 10% | J12: =ROUND(H12,-2) -> 180000 | K12: =CEILING(H12,1000) -> 180000 | L12: =FLOOR(H12,1000) -> 180000
A13: P011 | B13: Laptop | C13: East | D13: Jay Patel | E13: June | F13: 750 | G13: 2 | H13: =F13*G13 -> 1500 | I13: =IF(H13>=50000,"10%","5%") -> 5% | J13: =ROUND(H13,-2) -> 1500 | K13: =CEILING(H13,1000) -> 2000 | L13: =FLOOR(H13,1000) -> 1000 | O13: Sales by Salesperson
A14: P012 | B14: Mouse | C14: West | D14: Neha Shah | E14: June | F14: 1800 | G14: 18 | H14: =F14*G14 -> 32400 | I14: =IF(H14>=50000,"10%","5%") -> 5% | J14: =ROUND(H14,-2) -> 32400 | K14: =CEILING(H14,1000) -> 33000 | L14: =FLOOR(H14,1000) -> 32000 | O14: =INDEX(H3:H22,MATCH("Vandita Patel",D3:D22,0)) -> 15000
A15: P013 | B15: Keyboard | C15: North | D15: Harsh Patel | E15: July | F15: 13000 | G15: 9 | H15: =F15*G15 -> 117000 | I15: =IF(H15>=50000,"10%","5%") -> 10% | J15: =ROUND(H15,-2) -> 117000 | K15: =CEILING(H15,1000) -> 117000 | L15: =FLOOR(H15,1000) -> 117000
A16: P014 | B16: Moniter | C16: South | D16: Pooja Patel | E16: July | F16: 17000 | G16: 5 | H16: =F16*G16 -> 85000 | I16: =IF(H16>=50000,"10%","5%") -> 10% | J16: =ROUND(H16,-2) -> 85000 | K16: =CEILING(H16,1000) -> 85000 | L16: =FLOOR(H16,1000) -> 85000 | O16: Find Unit Price by Product Code
A17: P015 | B17: Printer | C17: East | D17: Dev Patel | E17: Aug | F17: 58000 | G17: 2 | H17: =F17*G17 -> 116000 | I17: =IF(H17>=50000,"10%","5%") -> 10% | J17: =ROUND(H17,-2) -> 116000 | K17: =CEILING(H17,1000) -> 116000 | L17: =FLOOR(H17,1000) -> 116000 | O17: =VLOOKUP("P005",A3:H22,6,FALSE) -> 18000
A18: P016 | B18: Laptop | C18: West | D18: Mansi Patel | E18: Aug | F18: 850 | G18: 1 | H18: =F18*G18 -> 850 | I18: =IF(H18>=50000,"10%","5%") -> 5% | J18: =ROUND(H18,-2) -> 900 | K18: =CEILING(H18,1000) -> 1000 | L18: =FLOOR(H18,1000) -> 0
A19: P017 | B19: Mouse | C19: North | D19: Dhruv Shah | E19: Sep | F19: 1600 | G19: 12 | H19: =F19*G19 -> 19200 | I19: =IF(H19>=50000,"10%","5%") -> 5% | J19: =ROUND(H19,-2) -> 19200 | K19: =CEILING(H19,1000) -> 20000 | L19: =FLOOR(H19,1000) -> 19000 | O19: Average Laptop Sales
A20: P018 | B20: Keyboard | C20: South | D20: Het Patel | E20: Sep | F20: 12500 | G20: 7 | H20: =F20*G20 -> 87500 | I20: =IF(H20>=50000,"10%","5%") -> 10% | J20: =ROUND(H20,-2) -> 87500 | K20: =CEILING(H20,1000) -> 88000 | L20: =FLOOR(H20,1000) -> 87000 | O20: =AVERAGEIFS(H3:H22,B3:B22,"Laptop") -> 43087.5
A21: P019 | B21: Moniter | C21: East | D21: Khushi Patel | E21: Oct | F21: 17500 | G21: 3 | H21: =F21*G21 -> 52500 | I21: =IF(H21>=50000,"10%","5%") -> 10% | J21: =ROUND(H21,-2) -> 52500 | K21: =CEILING(H21,1000) -> 53000 | L21: =FLOOR(H21,1000) -> 52000
A22: P020 | B22: Printer | C22: West | D22: Ronak Patel | E22: Oct | F22: 62000 | G22: 2 | H22: =F22*G22 -> 124000 | I22: =IF(H22>=50000,"10%","5%") -> 10% | J22: =ROUND(H22,-2) -> 124000 | K22: =CEILING(H22,1000) -> 124000 | L22: =FLOOR(H22,1000) -> 124000 | O22: South Region Orders Above ₹20,000
O23: =COUNTIFS(C:C,"South",H:H,">20000") -> 4
O25: Laptop ki position
C26: Only Laptop Records | O26: =_xlfn.XMATCH("Laptop",B:B) -> 3
C27: Product code | D27: Product | E27: Region | F27: Salesperson | G27: Month | H27: Unit Price | I27: Qty | J27: Total Sales
C28: {=_xlfn._xlws.FILTER(A3:H22,B3:B22="Laptop")} -> P001 | D28: Laptop | E28: North | F28: Tej Patel | G28: Jan | H28: 55000 | I28: 2 | J28: 110000 | O28: Salesperson Diya Patel ki Total Sales
C29: P006 | D29: Laptop | E29: South | F29: Priya Patel | G29: March | H29: 60000 | I29: 1 | J29: 60000 | O29: =INDEX(H:H,MATCH("Diya Patel",D:D,0)) -> 12000
C30: P011 | D30: Laptop | E30: East | F30: Jay Patel | G30: June | H30: 750 | I30: 2 | J30: 1500
C31: P016 | D31: Laptop | E31: West | F31: Mansi Patel | G31: Aug | H31: 850 | I31: 1 | J31: 850 | O31: Position of products
O32: =_xlfn.XMATCH("Printer",B3:B22) -> 5
AA40: Row Labels | AB40: Sum of Total Sales | AC40: Sum of Unit Price
AA41: Keyboard | AB41: 233900 | AC41: 28800
AA42: April | AB42: 14400 | AC42: 1800
AA43: Feb | AB43: 15000 | AC43: 1500
AA44: Sep | AB44: 87500 | AC44: 12500
AA45: July | AB45: 117000 | AC45: 13000
AA46: Laptop | AB46: 172350 | AC46: 116600
AA47: March | AB47: 60000 | AC47: 60000
AA48: Jan | AB48: 110000 | AC48: 55000
AA49: Aug | AB49: 850 | AC49: 850
...

Sheet Employee Data
A1: EMP ID | B1: Employee Name | C1: Department | D1: Date of Birth | E1: Age | F1: Date of Joining | G1: Experience | H1: Days Since Joining | I1: Salary | K1: Dashboard
A3: EMP001 | B3: Tej Patel | C3: IT | D3: 38056 | E3: =DATEDIF(D3,TODAY(),"Y")&" Years" -> 22 Years | F3: 45458 | G3: =DATEDIF(F3,TODAY(),"Y") & " Years " & DATEDIF(F3,TODAY(),"YM") & " Months" -> 2 Years 0 Months | H3: =DATEDIF(F3,TODAY(),"D") & " Days" -> 743 Days | I3: 68000
A4: EMP002 | B4: Diya Patel | C4: Sales | D4: 38213 | E4: =DATEDIF(D4,TODAY(),"Y")&" Years" -> 21 Years | F4: 45459 | G4: =DATEDIF(F4,TODAY(),"Y") & " Years " & DATEDIF(F4,TODAY(),"YM") & " Months" -> 2 Years 0 Months | H4: =DATEDIF(F4,TODAY(),"D") & " Days" -> 742 Days | I4: 65000 | K4: Salary by Employee Id 010 | O4: Employee name of Employee 010
A5: EMP003 | B5: Vandita Patel | C5: HR | D5: 36899 | E5: =DATEDIF(D5,TODAY(),"Y")&" Years" -> 25 Years | F5: 45462 | G5: =DATEDIF(F5,TODAY(),"Y") & " Years " & DATEDIF(F5,TODAY(),"YM") & " Months" -> 2 Years 0 Months | H5: =DATEDIF(F5,TODAY(),"D") & " Days" -> 739 Days | I5: 62000 | K5: =_xlfn.XLOOKUP("EMP010",A:A,I:I) -> 57000 | O5: =_xlfn.XLOOKUP("EMP010",A:A,B:B) -> Kavya Patel
A6: EMP004 | B6: Krish Patel | C6: Finance | D6: 38447 | E6: =DATEDIF(D6,TODAY(),"Y")&" Years" -> 21 Years | F6: 45818 | G6: =DATEDIF(F6,TODAY(),"Y") & " Years " & DATEDIF(F6,TODAY(),"YM") & " Months" -> 1 Years 0 Months | H6: =DATEDIF(F6,TODAY(),"D") & " Days" -> 383 Days | I6: 35000
A7: EMP005 | B7: Meet Shah | C7: IT | D7: 38548 | E7: =DATEDIF(D7,TODAY(),"Y")&" Years" -> 20 Years | F7: 45463 | G7: =DATEDIF(F7,TODAY(),"Y") & " Years " & DATEDIF(F7,TODAY(),"YM") & " Months" -> 2 Years 0 Months | H7: =DATEDIF(F7,TODAY(),"D") & " Days" -> 738 Days | I7: 55000 | K7: Total salary of all employee | O7: Average Salary (IT Department)
A8: EMP006 | B8: Priya Patel | C8: HR | D8: 38677 | E8: =DATEDIF(D8,TODAY(),"Y")&" Years" -> 20 Years | F8: 46183 | G8: =DATEDIF(F8,TODAY(),"Y") & " Years " & DATEDIF(F8,TODAY(),"YM") & " Months" -> 0 Years 0 Months | H8: =DATEDIF(F8,TODAY(),"D") & " Days" -> 18 Days | I8: 42000 | K8: =SUM(INDIRECT(AM67)) -> 913189 | O8: =AVERAGEIF(C:C,"IT",I:I) -> 52166.667
A9: EMP007 | B9: Yash Patel | C9: Sales | D9: 38414 | E9: =DATEDIF(D9,TODAY(),"Y")&" Years" -> 21 Years | F9: 45820 | G9: =DATEDIF(F9,TODAY(),"Y") & " Years " & DATEDIF(F9,TODAY(),"YM") & " Months" -> 1 Years 0 Months | H9: =DATEDIF(F9,TODAY(),"D") & " Days" -> 381 Days | I9: 60000
A10: EMP008 | B10: Riya Shah | C10: IT | D10: 38614 | E10: =DATEDIF(D10,TODAY(),"Y")&" Years" -> 20 Years | F10: 45461 | G10: =DATEDIF(F10,TODAY(),"Y") & " Years " & DATEDIF(F10,TODAY(),"YM") & " Months" -> 2 Years 0 Months | H10: =DATEDIF(F10,TODAY(),"D") & " Days" -> 740 Days | I10: 48000 | M10: HR Employees with Salary >35000
A11: EMP009 | B11: Aarav Patel | C11: Finance | D11: 38360 | E11: =DATEDIF(D11,TODAY(),"Y")&" Years" -> 21 Years | F11: 45465 | G11: =DATEDIF(F11,TODAY(),"Y") & " Years " & DATEDIF(F11,TODAY(),"YM") & " Months" -> 2 Years 0 Months | H11: =DATEDIF(F11,TODAY(),"D") & " Days" -> 736 Days | I11: 39000 | M11: =COUNTIFS(C:C,"HR",I:I,">35000") -> 5
A12: EMP010 | B12: Kavya Patel | C12: HR | D12: 38394 | E12: =DATEDIF(D12,TODAY(),"Y")&" Years" -> 21 Years | F12: 45816 | G12: =DATEDIF(F12,TODAY(),"Y") & " Years " & DATEDIF(F12,TODAY(),"YM") & " Months" -> 1 Years 0 Months | H12: =DATEDIF(F12,TODAY(),"D") & " Days" -> 385 Days | I12: 57000
A13: EMP011 | B13: Jay Patel | C13: IT | D13: 38711 | E13: =DATEDIF(D13,TODAY(),"Y")&" Years" -> 20 Years | F13: 45468 | G13: =DATEDIF(F13,TODAY(),"Y") & " Years " & DATEDIF(F13,TODAY(),"YM") & " Months" -> 2 Years 0 Months | H13: =DATEDIF(F13,TODAY(),"D") & " Days" -> 733 Days | I13: 52000 | M13: Row Labels | N13: Sum of Salary
A14: EMP012 | B14: Neha Shah | C14: Sales | D14: 38626 | E14: =DATEDIF(D14,TODAY(),"Y")&" Years" -> 20 Years | F14: 46182 | G14: =DATEDIF(F14,TODAY(),"Y") & " Years " & DATEDIF(F14,TODAY(),"YM") & " Months" -> 0 Years 0 Months | H14: =DATEDIF(F14,TODAY(),"D") & " Days" -> 19 Days | I14: 37000 | M14: 0 Years 0 Months
A15: EMP013 | B15: Harsh Patel | C15: Finance | D15: 38456 | E15: =DATEDIF(D15,TODAY(),"Y")&" Years" -> 21 Years | F15: 45459 | G15: =DATEDIF(F15,TODAY(),"Y") & " Years " & DATEDIF(F15,TODAY(),"YM") & " Months" -> 2 Years 0 Months | H15: =DATEDIF(F15,TODAY(),"D") & " Days" -> 742 Days | I15: 43000 | M15: HR | N15: 42000
A16: EMP014 | B16: Pooja Patel | C16: HR | D16: 38489 | E16: =DATEDIF(D16,TODAY(),"Y")&" Years" -> 21 Years | F16: 45825 | G16: =DATEDIF(F16,TODAY(),"Y") & " Years " & DATEDIF(F16,TODAY(),"YM") & " Months" -> 1 Years 0 Months | H16: =DATEDIF(F16,TODAY(),"D") & " Days" -> 376 Days | I16: 59000 | M16: Sales | N16: 94000
A17: EMP015 | B17: Dev Patel | C17: IT | D17: 38381 | E17: =DATEDIF(D17,TODAY(),"Y")&" Years" -> 21 Years | F17: 45458 | G17: =DATEDIF(F17,TODAY(),"Y") & " Years " & DATEDIF(F17,TODAY(),"YM") & " Months" -> 2 Years 0 Months | H17: =DATEDIF(F17,TODAY(),"D") & " Days" -> 743 Days | I17: 36000 | M17: 1 Years 0 Months
A18: EMP016 | B18: Mansi Patel | C18: Sales | D18: 38555 | E18: =DATEDIF(D18,TODAY(),"Y")&" Years" -> 20 Years | F18: 46183 | G18: =DATEDIF(F18,TODAY(),"Y") & " Years " & DATEDIF(F18,TODAY(),"YM") & " Months" -> 0 Years 0 Months | H18: =DATEDIF(F18,TODAY(),"D") & " Days" -> 18 Days | I18: 57000 | M18: Finance | N18: 35000
A19: EMP017 | B19: Dhruv Shah | C19: Finance | D19: 38580 | E19: =DATEDIF(D19,TODAY(),"Y")&" Years" -> 20 Years | F19: 45461 | G19: =DATEDIF(F19,TODAY(),"Y") & " Years " & DATEDIF(F19,TODAY(),"YM") & " Months" -> 2 Years 0 Months | H19: =DATEDIF(F19,TODAY(),"D") & " Days" -> 740 Days | I19: 41000 | M19: HR | N19: 154000
A20: EMP018 | B20: Het Patel | C20: HR | D20: 38665 | E20: =DATEDIF(D20,TODAY(),"Y")&" Years" -> 20 Years | F20: 45828 | G20: =DATEDIF(F20,TODAY(),"Y") & " Years " & DATEDIF(F20,TODAY(),"YM") & " Months" -> 1 Years 0 Months | H20: =DATEDIF(F20,TODAY(),"D") & " Days" -> 373 Days | I20: 38000 | M20: Sales | N20: 60000
A21: EMP019 | B21: Khushi Patel | C21: IT | D21: 38688 | E21: =DATEDIF(D21,TODAY(),"Y")&" Years" -> 20 Years | F21: 45455 | G21: =DATEDIF(F21,TODAY(),"Y") & " Years " & DATEDIF(F21,TODAY(),"YM") & " Months" -> 2 Years 0 Months | H21: =DATEDIF(F21,TODAY(),"D") & " Days" -> 746 Days | I21: 54000 | M21: 2 Years 0 Months
A22: EMP020 | B22: Ronak Patel | C22: Sales | D22: 38441 | E22: =DATEDIF(D22,TODAY(),"Y")&" Years" -> 21 Years | F22: 45465 | G22: =DATEDIF(F22,TODAY(),"Y") & " Years " & DATEDIF(F22,TODAY(),"YM") & " Months" -> 2 Years 0 Months | H22: =DATEDIF(F22,TODAY(),"D") & " Days" -> 736 Days | I22: 46000 | M22: Finance | N22: 123000
M23: HR | N23: 62000
M24: IT | N24: 313000
M25: Sales | N25: 111000
M26: Grand Total | N26: 994000
AM67: F:F
